[2024-05-04T11:51:37.066+0000] {task_context_logger.py:104} ERROR - Executor reports task instance <TaskInstance: emaildag.emailfunc scheduled__2024-04-30T00:00:00+00:00 [queued]> finished (failed) although the task says it's queued. (Info: None) Was the task killed externally?
