[2024-05-04T11:44:26.490+0000] {task_context_logger.py:104} ERROR - Executor reports task instance <TaskInstance: emaildag.testingfunc scheduled__2024-04-29T00:00:00+00:00 [queued]> finished (failed) although the task says it's queued. (Info: None) Was the task killed externally?
